<?xml version = '1.0'?>

<sdf version ='1.4'>
	<model name="kiro_robot">

	<!--It is easy in first make model static.-->
	<static>false</static>

	<link name='head'>
		<pose>0 0 .035 0 -1.57 0</pose>

		<collision name='head_collision'>
			<pose> 0 0 -0.025 0 0 0 </pose>
			<geometry>
				<cylinder>
					<radius>.035</radius>
					<length>.08</length>
				</cylinder>
			</geometry>
		</collision>

		<visual name='head_visual'>
			<geometry>
				<cylinder>
					<radius>.035</radius>
					<length>.13</length>
				</cylinder>
			</geometry>
		</visual>

		<visual name='head_pad_visual'>
			<pose> -0.025 0 0 0 0 0</pose>
			<geometry>
				<box>
					<size>0.02 0.035 0.13</size>
				</box>
			</geometry>
		</visual>

		<collision name='head_pad_collision'>
			<pose> -0.025 0 -0.025 0 0 0</pose>
			<geometry>
				<box>
					<size>0.02 0.035 0.08</size>
				</box>
			</geometry>
		</collision>
	</link>

	<link name='body1'>
		<pose>-0.1 0 .035 0 -1.57 0</pose>

		<collision name='body1_collision'>
			<pose> 0 0 -0.025 0 0 0 </pose>
			<geometry>
				<cylinder>
					<radius>.035</radius>
					<length>.08</length>
				</cylinder>
			</geometry>
		</collision>

		<visual name='body1_visual'>
			<geometry>
				<cylinder>
					<radius>.035</radius>
					<length>.13</length>
				</cylinder>
			</geometry>
			<material>
			<ambient>0 0 0.75 1</ambient>
			<diffuse>0 0 0.75 1</diffuse>
			</material>
		</visual>

		<visual name='body1_pad_visual'>
			<pose> -0.025 0 0 0 0 0</pose>
			<geometry>
				<box>
					<size>0.02 0.035 0.13</size>
				</box>
			</geometry>
			<material>
			<ambient>0 0 0.75 1</ambient>
			<diffuse>0 0 0.75 1</diffuse>
			</material>
		</visual>

		<collision name='body1_pad_collision'>
			<pose> -0.025 0 -0.025 0 0 0</pose>
			<geometry>
				<box>
					<size>0.02 0.035 0.08</size>
				</box>
			</geometry>
		</collision>
	</link>

	<link name='body2'>
		<pose>-0.2 0 .035 0 -1.57 0</pose>

		<collision name='body2_collision'>
			<pose> 0 0 -0.025 0 0 0 </pose>
			<geometry>
				<cylinder>
					<radius>.035</radius>
					<length>.08</length>
				</cylinder>
			</geometry>
		</collision>

		<visual name='body2_visual'>
			<geometry>
				<cylinder>
					<radius>.035</radius>
					<length>.13</length>
				</cylinder>
			</geometry>
		</visual>

		<visual name='body2_pad_visual'>
			<pose> -0.025 0 0 0 0 0</pose>
			<geometry>
				<box>
					<size>0.02 0.035 0.13</size>
				</box>
			</geometry>
		</visual>

		<collision name='body2_pad_collision'>
			<pose> -0.025 0 -0.025 0 0 0</pose>
			<geometry>
				<box>
					<size>0.02 0.035 0.08</size>
				</box>
			</geometry>
		</collision>
	</link>

	<link name='body3'>
		<pose>-0.3 0 .035 0 -1.57 0</pose>

		<collision name='body3_collision'>
			<pose> 0 0 -0.025 0 0 0 </pose>
			<geometry>
				<cylinder>
					<radius>.035</radius>
					<length>.08</length>
				</cylinder>
			</geometry>
		</collision>

		<visual name='body3_visual'>
			<geometry>
				<cylinder>
					<radius>.035</radius>
					<length>.13</length>
				</cylinder>
			</geometry>
			<material>
			<ambient>0 0 0.75 1</ambient>
			<diffuse>0 0 0.75 1</diffuse>
			</material>
		</visual>

		<visual name='body3_pad_visual'>
			<pose> -0.025 0 0 0 0 0</pose>
			<geometry>
				<box>
					<size>0.02 0.035 0.13</size>
				</box>
			</geometry>
			<material>
			<ambient>0 0 0.75 1</ambient>
			<diffuse>0 0 0.75 1</diffuse>
			</material>
		</visual>

		<collision name='body3_pad_collision'>
			<pose> -0.025 0 -0.025 0 0 0</pose>
			<geometry>
				<box>
					<size>0.02 0.035 0.08</size>
				</box>
			</geometry>
		</collision>
	</link>

	<link name='body4'>
		<pose>-0.4 0 .035 0 -1.57 0</pose>

		<collision name='body4_collision'>
			<pose> 0 0 -0.025 0 0 0 </pose>
			<geometry>
				<cylinder>
					<radius>.035</radius>
					<length>.08</length>
				</cylinder>
			</geometry>
		</collision>

		<visual name='body4_visual'>
			<geometry>
				<cylinder>
					<radius>.035</radius>
					<length>.13</length>
				</cylinder>
			</geometry>
		</visual>

		<visual name='body4_pad_visual'>
			<pose> -0.025 0 0 0 0 0</pose>
			<geometry>
				<box>
					<size>0.02 0.035 0.13</size>
				</box>
			</geometry>
		</visual>

		<collision name='body4_pad_collision'>
			<pose> -0.025 0 -0.025 0 0 0</pose>
			<geometry>
				<box>
					<size>0.02 0.035 0.08</size>
				</box>
			</geometry>
		</collision>
	</link>

	<link name='body5'>
		<pose>-0.5 0 .035 0 -1.57 0</pose>

		<collision name='body5_collision'>
			<pose> 0 0 -0.025 0 0 0 </pose>
			<geometry>
				<cylinder>
					<radius>.035</radius>
					<length>.08</length>
				</cylinder>
			</geometry>
		</collision>

		<visual name='body5_visual'>
			<geometry>
				<cylinder>
					<radius>.035</radius>
					<length>.13</length>
				</cylinder>
			</geometry>
			<material>
			<ambient>0 0 0.75 1</ambient>
			<diffuse>0 0 0.75 1</diffuse>
			</material>
		</visual>

		<visual name='body5_pad_visual'>
			<pose> -0.025 0 0 0 0 0</pose>
			<geometry>
				<box>
					<size>0.02 0.035 0.13</size>
				</box>
			</geometry>
			<material>
			<ambient>0 0 0.75 1</ambient>
			<diffuse>0 0 0.75 1</diffuse>
			</material>
		</visual>

		<collision name='body5_pad_collision'>
			<pose> -0.025 0 -0.025 0 0 0</pose>
			<geometry>
				<box>
					<size>0.02 0.035 0.08</size>
				</box>
			</geometry>
		</collision>
	</link>

	<link name='body6'>
		<pose>-0.6 0 .035 0 -1.57 0</pose>

		<collision name='body6_collision'>
			<pose> 0 0 -0.025 0 0 0 </pose>
			<geometry>
				<cylinder>
					<radius>.035</radius>
					<length>.08</length>
				</cylinder>
			</geometry>
		</collision>

		<visual name='body6_visual'>
			<geometry>
				<cylinder>
					<radius>.035</radius>
					<length>.13</length>
				</cylinder>
			</geometry>
		</visual>

		<visual name='body6_pad_visual'>
			<pose> -0.025 0 0 0 0 0</pose>
			<geometry>
				<box>
					<size>0.02 0.035 0.13</size>
				</box>
			</geometry>
		</visual>

		<collision name='body6_pad_collision'>
			<pose> -0.025 0 -0.025 0 0 0</pose>
			<geometry>
				<box>
					<size>0.02 0.035 0.08</size>
				</box>
			</geometry>
		</collision>
	</link>

	<link name='body7'>
		<pose>-0.7 0 .035 0 -1.57 0</pose>

		<collision name='body7_collision'>
			<pose> 0 0 -0.025 0 0 0 </pose>
			<geometry>
				<cylinder>
					<radius>.035</radius>
					<length>.08</length>
				</cylinder>
			</geometry>
		</collision>

		<visual name='body7_visual'>
			<geometry>
				<cylinder>
					<radius>.035</radius>
					<length>.13</length>
				</cylinder>
			</geometry>
			<material>
			<ambient>0 0 0.75 1</ambient>
			<diffuse>0 0 0.75 1</diffuse>
			</material>
		</visual>

		<visual name='body7_pad_visual'>
			<pose> -0.025 0 0 0 0 0</pose>
			<geometry>
				<box>
					<size>0.02 0.035 0.13</size>
				</box>
			</geometry>
			<material>
			<ambient>0 0 0.75 1</ambient>
			<diffuse>0 0 0.75 1</diffuse>
			</material>
		</visual>

		<collision name='body7_pad_collision'>
			<pose> -0.025 0 -0.025 0 0 0</pose>
			<geometry>
				<box>
					<size>0.02 0.035 0.08</size>
				</box>
			</geometry>
		</collision>
	</link>

	<link name='body8'>
		<pose>-0.8 0 .035 0 -1.57 0</pose>

		<collision name='body8_collision'>
			<pose> 0 0 -0.025 0 0 0 </pose>
			<geometry>
				<cylinder>
					<radius>.035</radius>
					<length>.08</length>
				</cylinder>
			</geometry>
		</collision>

		<visual name='body8_visual'>
			<geometry>
				<cylinder>
					<radius>.035</radius>
					<length>.13</length>
				</cylinder>
			</geometry>
		</visual>

		<visual name='body8_pad_visual'>
			<pose> -0.025 0 0 0 0 0</pose>
			<geometry>
				<box>
					<size>0.02 0.035 0.13</size>
				</box>
			</geometry>
		</visual>

		<collision name='body8_pad_collision'>
			<pose> -0.025 0 -0.025 0 0 0</pose>
			<geometry>
				<box>
					<size>0.02 0.035 0.08</size>
				</box>
			</geometry>
		</collision>
	</link>

	<link name='body9'>
		<pose>-0.9 0 .035 0 -1.57 0</pose>

		<collision name='body9_collision'>
			<pose> 0 0 -0.025 0 0 0 </pose>
			<geometry>
				<cylinder>
					<radius>.035</radius>
					<length>.08</length>
				</cylinder>
			</geometry>
		</collision>

		<visual name='body9_visual'>
			<geometry>
				<cylinder>
					<radius>.035</radius>
					<length>.13</length>
				</cylinder>
			</geometry>
			<material>
			<ambient>0 0 0.75 1</ambient>
			<diffuse>0 0 0.75 1</diffuse>
			</material>
		</visual>

		<visual name='body9_pad_visual'>
			<pose> -0.025 0 0 0 0 0</pose>
			<geometry>
				<box>
					<size>0.02 0.035 0.13</size>
				</box>
			</geometry>
			<material>
			<ambient>0 0 0.75 1</ambient>
			<diffuse>0 0 0.75 1</diffuse>
			</material>
		</visual>

		<collision name='body9_pad_collision'>
			<pose> -0.025 0 -0.025 0 0 0</pose>
			<geometry>
				<box>
					<size>0.02 0.035 0.08</size>
				</box>
			</geometry>
		</collision>
	</link>

	<link name='body10'>
		<pose>-1.0 0 .035 0 -1.57 0</pose>

		<collision name='body10_collision'>
			<pose> 0 0 -0.025 0 0 0 </pose>
			<geometry>
				<cylinder>
					<radius>.035</radius>
					<length>.08</length>
				</cylinder>
			</geometry>
		</collision>

		<visual name='body10_visual'>
			<geometry>
				<cylinder>
					<radius>.035</radius>
					<length>.13</length>
				</cylinder>
			</geometry>
		</visual>

		<visual name='body10_pad_visual'>
			<pose> -0.025 0 0 0 0 0</pose>
			<geometry>
				<box>
					<size>0.02 0.035 0.13</size>
				</box>
			</geometry>
		</visual>

		<collision name='body10_pad_collision'>
			<pose> -0.025 0 -0.025 0 0 0</pose>
			<geometry>
				<box>
					<size>0.02 0.035 0.08</size>
				</box>
			</geometry>
		</collision>
	</link>

	<link name='tail'>
		<pose>-1.1 0 .035 0 -1.57 0</pose>

		<collision name='tail_collision'>
			<pose> 0 0 0 0 0 0 </pose>
			<geometry>
				<cylinder>
					<radius>.035</radius>
					<length>.13</length>
				</cylinder>
			</geometry>
		</collision>

		<visual name='tail_visual'>
			<geometry>
				<cylinder>
					<radius>.035</radius>
					<length>.13</length>
				</cylinder>
			</geometry>
			<material>
			<ambient>0 0 0.75 1</ambient>
			<diffuse>0 0 0.75 1</diffuse>
			</material>
		</visual>

		<visual name='tail_pad_visual'>
			<pose> -0.025 0 0 0 0 0</pose>
			<geometry>
				<box>
					<size>0.02 0.035 0.13</size>
				</box>
			</geometry>
			<material>
			<ambient>0 0 0.75 1</ambient>
			<diffuse>0 0 0.75 1</diffuse>
			</material>
		</visual>

		<collision name='tail_pad_collision'>
			<pose> -0.025 0 0 0 0 0</pose>
			<geometry>
				<box>
					<size>0.02 0.035 0.13</size>
				</box>
			</geometry>
		</collision>
	</link>
<!-- 
	<joint type="revolute" name="joint1">
		<pose>0.05 0 0.035 0 0 0</pose>
		<child>head</child>
		<parent>body1</parent>
		<axis>
			<xyz>0 1 0</xyz>
		</axix>
	</joint> -->

	<joint type="revolute" name="joint1">
        <pose>0 0 -0.05 0 0 0</pose>
        <parent>head</parent>
        <child>body1</child>
        <axis>
          <xyz>0 1 0</xyz>
			<limit>
				<lower> -1.22173 </lower>
				<upper> 1.22173 </upper>
				<!-- <effort> 7.8 </effort> -->
				<velocity> 8.16814 </velocity>
			</limit>
        </axis>
    </joint>

	<joint type="revolute" name="joint2">
        <pose>0 0 -0.05 0 0 0</pose>
        <parent>body1</parent>
        <child>body2</child>
        <axis>
          <xyz>0 0 1</xyz>
			<limit>
				<lower> -1.22173 </lower>
				<upper> 1.22173 </upper>
				<!-- <effort> 7.8 </effort> -->
				<velocity> 8.16814 </velocity>
			</limit>
        </axis>
    </joint>

	<joint type="revolute" name="joint3">
        <pose>0 0 -0.05 0 0 0</pose>
        <parent>body2</parent>
        <child>body3</child>
        <axis>
          <xyz>0 1 0</xyz>
			<limit>
				<lower> -1.22173 </lower>
				<upper> 1.22173 </upper>
				<!-- <effort> 7.8 </effort> -->
				<velocity> 8.16814 </velocity>
			</limit>
        </axis>
    </joint>

	<joint type="revolute" name="joint4">
        <pose>0 0 -0.05 0 0 0</pose>
        <parent>body3</parent>
        <child>body4</child>
        <axis>
          <xyz>0 0 1</xyz>
			<limit>
				<lower> -1.22173 </lower>
				<upper> 1.22173 </upper>
				<!-- <effort> 7.8 </effort> -->
				<velocity> 8.16814 </velocity>
			</limit>
        </axis>
    </joint>

	<joint type="revolute" name="joint5">
        <pose>0 0 -0.05 0 0 0</pose>
        <parent>body4</parent>
        <child>body5</child>
        <axis>
          <xyz>0 1 0</xyz>
			<limit>
				<lower> -1.22173 </lower>
				<upper> 1.22173 </upper>
				<!-- <effort> 7.8 </effort> -->
				<velocity> 8.16814 </velocity>
			</limit>
        </axis>
    </joint>

	<joint type="revolute" name="joint6">
        <pose>0 0 -0.05 0 0 0</pose>
        <parent>body5</parent>
        <child>body6</child>
        <axis>
          <xyz>0 0 1</xyz>
			<limit>
				<lower> -1.22173 </lower>
				<upper> 1.22173 </upper>
				<!-- <effort> 7.8 </effort> -->
				<velocity> 8.16814 </velocity>
			</limit>
        </axis>
    </joint>

	<joint type="revolute" name="joint7">
        <pose>0 0 -0.05 0 0 0</pose>
        <parent>body6</parent>
        <child>body7</child>
        <axis>
          <xyz>0 1 0</xyz>
			<limit>
				<lower> -1.22173 </lower>
				<upper> 1.22173 </upper>
				<!-- <effort> 7.8 </effort> -->
				<velocity> 8.16814 </velocity>
			</limit>
        </axis>
    </joint>

	<joint type="revolute" name="joint8">
        <pose>0 0 -0.05 0 0 0</pose>
        <parent>body7</parent>
        <child>body8</child>
        <axis>
          <xyz>0 0 1</xyz>
			<limit>
				<lower> -1.22173 </lower>
				<upper> 1.22173 </upper>
				<!-- <effort> 7.8 </effort> -->
				<velocity> 8.16814 </velocity>
			</limit>
        </axis>
    </joint>

	<joint type="revolute" name="joint9">
        <pose>0 0 -0.05 0 0 0</pose>
        <parent>body8</parent>
        <child>body9</child>
        <axis>
          <xyz>0 1 0</xyz>
			<limit>
				<lower> -1.22173 </lower>
				<upper> 1.22173 </upper>
				<!-- <effort> 7.8 </effort> -->
				<velocity> 8.16814 </velocity>
			</limit>
        </axis>
    </joint>

	<joint type="revolute" name="joint10">
        <pose>0 0 -0.05 0 0 0</pose>
        <parent>body9</parent>
        <child>body10</child>
        <axis>
          <xyz>0 1 0</xyz>
			<limit>
				<lower> -1.22173 </lower>
				<upper> 1.22173 </upper>
				<!-- <effort> 7.8 </effort> -->
				<velocity> 8.16814 </velocity>
			</limit>
        </axis>
    </joint>

	<joint type="revolute" name="joint11">
        <pose>0 0 -0.05 0 0 0</pose>
        <parent>body10</parent>
        <child>tail</child>
        <axis>
        	<xyz>0 1 0</xyz>
			<limit>
				<lower> -1.22173 </lower>
				<upper> 1.22173 </upper>
				<!-- <effort> 7.8 </effort> -->
				<velocity> 8.16814 </velocity>
			</limit>
        </axis>
    </joint>

	<gazebo>
		<self_collide> 1 </self_collide>
	</gazebo>

	<!--Hardlink created here-->
	</model>
</sdf>
