<?xml version="1.0" encoding="utf-8"?>
<!-- This URDF was automatically created by SolidWorks to URDF Exporter! Originally created by Stephen Brawner (brawner@gmail.com) 
     Commit Version: 1.5.1-0-g916b5db  Build Version: 1.5.7152.31018
     For more information, please see http://wiki.ros.org/sw_urdf_exporter -->
<robot
  name="Quadnake_Vertical_Leg">
  <link
    name="base_link">
    <inertial>
      <origin
        xyz="-0.0057706 0.21609 0.054307"
        rpy="0 0 0" />
      <mass
        value="0.52162" />
      <inertia
        ixx="0.013885"
        ixy="-4.1562E-06"
        ixz="2.4437E-07"
        iyy="0.00012457"
        iyz="6.6864E-05"
        izz="0.01389" />
    </inertial>
    <visual>
      <origin
        xyz="0 0 0"
        rpy="0 0 0" />
      <geometry>
        <mesh
          filename="package://Quadnake_Vertical_Leg/meshes/base_link.STL" />
      </geometry>
      <material
        name="">
        <color
          rgba="0.79216 0.81961 0.93333 1" />
      </material>
    </visual>
    <collision>
      <origin
        xyz="0 0 0"
        rpy="0 0 0" />
      <geometry>
        <mesh
          filename="package://Quadnake_Vertical_Leg/meshes/base_link.STL" />
      </geometry>
    </collision>
  </link>
  <link
    name="Link1">
    <inertial>
      <origin
        xyz="0.027707 -0.2055 -0.00026616"
        rpy="0 0 0" />
      <mass
        value="0.52162" />
      <inertia
        ixx="0.01389"
        ixy="-6.6864E-05"
        ixz="2.4437E-07"
        iyy="0.00012457"
        iyz="4.1562E-06"
        izz="0.013885" />
    </inertial>
    <visual>
      <origin
        xyz="0 0 0"
        rpy="0 0 0" />
      <geometry>
        <mesh
          filename="package://Quadnake_Vertical_Leg/meshes/Link1.STL" />
      </geometry>
      <material
        name="">
        <color
          rgba="0.79216 0.81961 0.93333 1" />
      </material>
    </visual>
    <collision>
      <origin
        xyz="0 0 0"
        rpy="0 0 0" />
      <geometry>
        <mesh
          filename="package://Quadnake_Vertical_Leg/meshes/Link1.STL" />
      </geometry>
    </collision>
  </link>
  <joint
    name="Joint1"
    type="continuous">
    <origin
      xyz="-0.0055044 -0.0266 0.010585"
      rpy="-1.5708 0 -1.5708" />
    <parent
      link="base_link" />
    <child
      link="Link1" />
    <axis
      xyz="1 0 0" />
  </joint>
  <link
    name="Link2">
    <inertial>
      <origin
        xyz="-0.0015429 -0.122 -0.00026616"
        rpy="0 0 0" />
      <mass
        value="0.52162" />
      <inertia
        ixx="0.01389"
        ixy="-6.6864E-05"
        ixz="2.4437E-07"
        iyy="0.00012457"
        iyz="4.1562E-06"
        izz="0.013885" />
    </inertial>
    <visual>
      <origin
        xyz="0 0 0"
        rpy="0 0 0" />
      <geometry>
        <mesh
          filename="package://Quadnake_Vertical_Leg/meshes/Link2.STL" />
      </geometry>
      <material
        name="">
        <color
          rgba="0.79216 0.81961 0.93333 1" />
      </material>
    </visual>
    <collision>
      <origin
        xyz="0 0 0"
        rpy="0 0 0" />
      <geometry>
        <mesh
          filename="package://Quadnake_Vertical_Leg/meshes/Link2.STL" />
      </geometry>
    </collision>
  </link>
  <joint
    name="Joint2"
    type="continuous">
    <origin
      xyz="0.02925 -0.0835 0"
      rpy="0 0 0" />
    <parent
      link="Link1" />
    <child
      link="Link2" />
    <axis
      xyz="0 0 1" />
  </joint>
  <link
    name="Link3">
    <inertial>
      <origin
        xyz="-0.0015429 -0.0495 -0.00026616"
        rpy="0 0 0" />
      <mass
        value="0.52162" />
      <inertia
        ixx="0.01389"
        ixy="-6.6864E-05"
        ixz="2.4437E-07"
        iyy="0.00012457"
        iyz="4.1562E-06"
        izz="0.013885" />
    </inertial>
    <visual>
      <origin
        xyz="0 0 0"
        rpy="0 0 0" />
      <geometry>
        <mesh
          filename="package://Quadnake_Vertical_Leg/meshes/Link3.STL" />
      </geometry>
      <material
        name="">
        <color
          rgba="0.79216 0.81961 0.93333 1" />
      </material>
    </visual>
    <collision>
      <origin
        xyz="0 0 0"
        rpy="0 0 0" />
      <geometry>
        <mesh
          filename="package://Quadnake_Vertical_Leg/meshes/Link3.STL" />
      </geometry>
    </collision>
  </link>
  <joint
    name="Joint3"
    type="continuous">
    <origin
      xyz="0 -0.0725 0"
      rpy="0 0 0" />
    <parent
      link="Link2" />
    <child
      link="Link3" />
    <axis
      xyz="0 0 1" />
  </joint>
  <link
    name="Link4">
    <inertial>
      <origin
        xyz="-0.0015429 0.0175 -0.00026616"
        rpy="0 0 0" />
      <mass
        value="0.52162" />
      <inertia
        ixx="0.01389"
        ixy="-6.6864E-05"
        ixz="2.4437E-07"
        iyy="0.00012457"
        iyz="4.1562E-06"
        izz="0.013885" />
    </inertial>
    <visual>
      <origin
        xyz="0 0 0"
        rpy="0 0 0" />
      <geometry>
        <mesh
          filename="package://Quadnake_Vertical_Leg/meshes/Link4.STL" />
      </geometry>
      <material
        name="">
        <color
          rgba="0.79216 0.81961 0.93333 1" />
      </material>
    </visual>
    <collision>
      <origin
        xyz="0 0 0"
        rpy="0 0 0" />
      <geometry>
        <mesh
          filename="package://Quadnake_Vertical_Leg/meshes/Link4.STL" />
      </geometry>
    </collision>
  </link>
  <joint
    name="Joint4"
    type="continuous">
    <origin
      xyz="0 -0.067 0"
      rpy="0 0 0" />
    <parent
      link="Link3" />
    <child
      link="Link4" />
    <axis
      xyz="0 0 1" />
  </joint>
  <link
    name="Link5">
    <inertial>
      <origin
        xyz="-0.0015429 0.0845 -0.00026616"
        rpy="0 0 0" />
      <mass
        value="0.52162" />
      <inertia
        ixx="0.01389"
        ixy="-6.6864E-05"
        ixz="2.4437E-07"
        iyy="0.00012457"
        iyz="4.1562E-06"
        izz="0.013885" />
    </inertial>
    <visual>
      <origin
        xyz="0 0 0"
        rpy="0 0 0" />
      <geometry>
        <mesh
          filename="package://Quadnake_Vertical_Leg/meshes/Link5.STL" />
      </geometry>
      <material
        name="">
        <color
          rgba="0.79216 0.81961 0.93333 1" />
      </material>
    </visual>
    <collision>
      <origin
        xyz="0 0 0"
        rpy="0 0 0" />
      <geometry>
        <mesh
          filename="package://Quadnake_Vertical_Leg/meshes/Link5.STL" />
      </geometry>
    </collision>
  </link>
  <joint
    name="Joint5"
    type="continuous">
    <origin
      xyz="0 -0.067 0"
      rpy="0 0 0" />
    <parent
      link="Link4" />
    <child
      link="Link5" />
    <axis
      xyz="0 0 1" />
  </joint>
  <link
    name="Link6">
    <inertial>
      <origin
        xyz="-0.0015429 0.1515 -0.00026616"
        rpy="0 0 0" />
      <mass
        value="0.52162" />
      <inertia
        ixx="0.01389"
        ixy="-6.6864E-05"
        ixz="2.4437E-07"
        iyy="0.00012457"
        iyz="4.1562E-06"
        izz="0.013885" />
    </inertial>
    <visual>
      <origin
        xyz="0 0 0"
        rpy="0 0 0" />
      <geometry>
        <mesh
          filename="package://Quadnake_Vertical_Leg/meshes/Link6.STL" />
      </geometry>
      <material
        name="">
        <color
          rgba="0.79216 0.81961 0.93333 1" />
      </material>
    </visual>
    <collision>
      <origin
        xyz="0 0 0"
        rpy="0 0 0" />
      <geometry>
        <mesh
          filename="package://Quadnake_Vertical_Leg/meshes/Link6.STL" />
      </geometry>
    </collision>
  </link>
  <joint
    name="Joint6"
    type="continuous">
    <origin
      xyz="0 -0.067 0"
      rpy="0 0 0" />
    <parent
      link="Link5" />
    <child
      link="Link6" />
    <axis
      xyz="0 0 1" />
  </joint>
  <link
    name="Link7">
    <inertial>
      <origin
        xyz="-0.2185 -0.0015429 -0.00026616"
        rpy="0 0 0" />
      <mass
        value="0.52162" />
      <inertia
        ixx="0.00012457"
        ixy="6.6864E-05"
        ixz="-4.1562E-06"
        iyy="0.01389"
        iyz="2.4437E-07"
        izz="0.013885" />
    </inertial>
    <visual>
      <origin
        xyz="0 0 0"
        rpy="0 0 0" />
      <geometry>
        <mesh
          filename="package://Quadnake_Vertical_Leg/meshes/Link7.STL" />
      </geometry>
      <material
        name="">
        <color
          rgba="0.79216 0.81961 0.93333 1" />
      </material>
    </visual>
    <collision>
      <origin
        xyz="0 0 0"
        rpy="0 0 0" />
      <geometry>
        <mesh
          filename="package://Quadnake_Vertical_Leg/meshes/Link7.STL" />
      </geometry>
    </collision>
  </link>
  <joint
    name="Joint7"
    type="continuous">
    <origin
      xyz="0 -0.067 0"
      rpy="0 0 0" />
    <parent
      link="Link6" />
    <child
      link="Link7" />
    <axis
      xyz="0 0 1" />
  </joint>
</robot>