<?xml version="1.0" ?>
<robot name="kiro_v2">
  <joint name="kiro_v2__1_joint" type="revolute">
    <parent link="kiro_v2__1_head"/>
    <child link="kiro_v2__2_link"/>
    <origin rpy="0       1.57079  0" xyz="-0.03549  0       0.029"/>
    <axis xyz="0  1  0"/>
    <limit effort="1.70775" lower="-1.57079632679" upper="1.57079632679" velocity="4.2"/>
  </joint>
  <joint name="kiro_v2__2_joint" type="revolute">
    <parent link="kiro_v2__2_link"/>
    <child link="kiro_v2__3_link"/>
    <origin rpy="0  0  0" xyz="0       0      -0.07099"/>
    <axis xyz="-1  0  0"/>
    <limit effort="1.70775" lower="-1.57079632679" upper="1.57079632679" velocity="4.2"/>
  </joint>
  <joint name="kiro_v2__3_joint" type="revolute">
    <parent link="kiro_v2__3_link"/>
    <child link="kiro_v2__4_link"/>
    <origin rpy="0  0  0" xyz="0       0      -0.07099"/>
    <axis xyz="0  1  0"/>
    <limit effort="1.70775" lower="-1.57079632679" upper="1.57079632679" velocity="4.2"/>
  </joint>
  <joint name="kiro_v2__4_joint" type="revolute">
    <parent link="kiro_v2__4_link"/>
    <child link="kiro_v2__5_link"/>
    <origin rpy="0  0  0" xyz="0       0      -0.07099"/>
    <axis xyz="-1  0  0"/>
    <limit effort="1.70775" lower="-1.57079632679" upper="1.57079632679" velocity="4.2"/>
  </joint>
  <joint name="kiro_v2__5_joint" type="revolute">
    <parent link="kiro_v2__5_link"/>
    <child link="kiro_v2__6_link"/>
    <origin rpy="0  0  0" xyz="0       0      -0.07099"/>
    <axis xyz="0  1  0"/>
    <limit effort="1.70775" lower="-1.57079632679" upper="1.57079632679" velocity="4.2"/>
  </joint>
  <joint name="kiro_v2__6_joint" type="revolute">
    <parent link="kiro_v2__6_link"/>
    <child link="kiro_v2__7_link"/>
    <origin rpy="0  0  0" xyz="0       0      -0.07099"/>
    <axis xyz="-1  0  0"/>
    <limit effort="1.70775" lower="-1.57079632679" upper="1.57079632679" velocity="4.2"/>
  </joint>
  <joint name="kiro_v2__7_joint" type="revolute">
    <parent link="kiro_v2__7_link"/>
    <child link="kiro_v2__8_link"/>
    <origin rpy="0  0  0" xyz="0       0      -0.07099"/>
    <axis xyz="0  1  0"/>
    <limit effort="1.70775" lower="-1.57079632679" upper="1.57079632679" velocity="4.2"/>
  </joint>
  <joint name="kiro_v2__8_joint" type="revolute">
    <parent link="kiro_v2__8_link"/>
    <child link="kiro_v2__9_link"/>
    <origin rpy="0  0  0" xyz="0       0      -0.07099"/>
    <axis xyz="-1  0  0"/>
    <limit effort="1.70775" lower="-1.57079632679" upper="1.57079632679" velocity="4.2"/>
  </joint>
  <joint name="kiro_v2__9_joint" type="revolute">
    <parent link="kiro_v2__9_link"/>
    <child link="kiro_v2__10_link"/>
    <origin rpy="0  0  0" xyz="0       0      -0.07099"/>
    <axis xyz="0  1  0"/>
    <limit effort="1.70775" lower="-1.57079632679" upper="1.57079632679" velocity="4.2"/>
  </joint>
  <joint name="kiro_v2__10_joint" type="revolute">
    <parent link="kiro_v2__10_link"/>
    <child link="kiro_v2__11_link"/>
    <origin rpy="0  0  0" xyz="0       0      -0.07099"/>
    <axis xyz="-1  0  0"/>
    <limit effort="1.70775" lower="-1.57079632679" upper="1.57079632679" velocity="4.2"/>
  </joint>
  <joint name="kiro_v2__11_joint" type="revolute">
    <parent link="kiro_v2__11_link"/>
    <child link="kiro_v2__12_tail"/>
    <origin rpy="0  0  0" xyz="0       0      -0.07099"/>
    <axis xyz="0  1  0"/>
    <limit effort="1.70775" lower="-1.57079632679" upper="1.57079632679" velocity="4.2"/>
  </joint>
  <link name="kiro_v2__1_head">
    <inertial>
      <mass value="0.192"/>
      <origin rpy="0  0  0" xyz="0  0  0"/>
      <inertia ixx="390949e-9" ixy="-59e-9" ixz="346e-9" iyy="400197e-9" iyz="355e-9" izz="73725e-9"/>
    </inertial>
    <collision name="kiro_v2__1_head_collision">
      <origin rpy="0       1.57079  0" xyz="0     0     0.029"/>
      <geometry>
        <cylinder length=".092" radius=".029"/>
      </geometry>
    </collision>
    <collision name="kiro_v2__1_head_pad_collision">
      <origin rpy="0       1.57079  0" xyz="0      0      0.0025"/>
      <geometry>
        <box size="0.005 0.020 0.092"/>
      </geometry>
    </collision>
    <visual name="kiro_v2__1_head_visual">
      <origin rpy="0       1.57079  0" xyz="0     0     0.029"/>
      <geometry>
        <cylinder length=".092" radius=".029"/>
      </geometry>
    </visual>
    <visual name="kiro_v2__1_head_pad_visual">
      <origin rpy="0       1.57079  0" xyz="0      0      0.0025"/>
      <geometry>
        <box size="0.005 0.020 0.092"/>
      </geometry>
    </visual>
  </link>
  <link name="kiro_v2__2_link">
    <inertial>
      <mass value="0.192"/>
      <origin rpy="0  0  0" xyz="0  0  0"/>
      <inertia ixx="390949e-9" ixy="-59e-9" ixz="346e-9" iyy="400197e-9" iyz="355e-9" izz="73725e-9"/>
    </inertial>
    <collision name="kiro_v2__2_link_collision">
      <origin rpy="0  0  0" xyz="0     0    -0.046"/>
      <geometry>
        <cylinder length=".071" radius=".029"/>
      </geometry>
    </collision>
    <collision name="kiro_v2__2_link_pad_collision">
      <origin rpy="0  0  0" xyz="0.0265  0     -0.046"/>
      <geometry>
        <box size="0.005 0.020 0.071"/>
      </geometry>
    </collision>
    <visual name="kiro_v2__2_link_visual">
      <origin rpy="0  0  0" xyz="0       0      -0.03549"/>
      <geometry>
        <cylinder length=".092" radius=".029"/>
      </geometry>
    </visual>
    <visual name="kiro_v2__2_link_pad_visual">
      <origin rpy="0  0  0" xyz="0.0265   0      -0.03549"/>
      <geometry>
        <box size="0.005 0.020 0.092"/>
      </geometry>
    </visual>
  </link>
  <link name="kiro_v2__3_link">
    <inertial>
      <mass value="0.192"/>
      <origin rpy="0  0  0" xyz="0  0  0"/>
      <inertia ixx="390949e-9" ixy="-59e-9" ixz="346e-9" iyy="400197e-9" iyz="355e-9" izz="73725e-9"/>
    </inertial>
    <collision name="kiro_v2__3_link_collision">
      <origin rpy="0  0  0" xyz="0     0    -0.046"/>
      <geometry>
        <cylinder length=".071" radius=".029"/>
      </geometry>
    </collision>
    <collision name="kiro_v2__3_link_pad_collision">
      <origin rpy="0  0  0" xyz="0.0265  0     -0.046"/>
      <geometry>
        <box size="0.005 0.020 0.071"/>
      </geometry>
    </collision>
    <visual name="kiro_v2__3_link_visual">
      <origin rpy="0  0  0" xyz="0       0      -0.03549"/>
      <geometry>
        <cylinder length=".092" radius=".029"/>
      </geometry>
    </visual>
    <visual name="kiro_v2__3_link_pad_visual">
      <origin rpy="0  0  0" xyz="0.0265   0      -0.03549"/>
      <geometry>
        <box size="0.005 0.020 0.092"/>
      </geometry>
    </visual>
  </link>
  <link name="kiro_v2__4_link">
    <inertial>
      <mass value="0.192"/>
      <origin rpy="0  0  0" xyz="0  0  0"/>
      <inertia ixx="390949e-9" ixy="-59e-9" ixz="346e-9" iyy="400197e-9" iyz="355e-9" izz="73725e-9"/>
    </inertial>
    <collision name="kiro_v2__4_link_collision">
      <origin rpy="0  0  0" xyz="0     0    -0.046"/>
      <geometry>
        <cylinder length=".071" radius=".029"/>
      </geometry>
    </collision>
    <collision name="kiro_v2__4_link_pad_collision">
      <origin rpy="0  0  0" xyz="0.0265  0     -0.046"/>
      <geometry>
        <box size="0.005 0.020 0.071"/>
      </geometry>
    </collision>
    <visual name="kiro_v2__4_link_visual">
      <origin rpy="0  0  0" xyz="0       0      -0.03549"/>
      <geometry>
        <cylinder length=".092" radius=".029"/>
      </geometry>
    </visual>
    <visual name="kiro_v2__4_link_pad_visual">
      <origin rpy="0  0  0" xyz="0.0265   0      -0.03549"/>
      <geometry>
        <box size="0.005 0.020 0.092"/>
      </geometry>
    </visual>
  </link>
  <link name="kiro_v2__5_link">
    <inertial>
      <mass value="0.192"/>
      <origin rpy="0  0  0" xyz="0  0  0"/>
      <inertia ixx="390949e-9" ixy="-59e-9" ixz="346e-9" iyy="400197e-9" iyz="355e-9" izz="73725e-9"/>
    </inertial>
    <collision name="kiro_v2__5_link_collision">
      <origin rpy="0  0  0" xyz="0     0    -0.046"/>
      <geometry>
        <cylinder length=".071" radius=".029"/>
      </geometry>
    </collision>
    <collision name="kiro_v2__5_link_pad_collision">
      <origin rpy="0  0  0" xyz="0.0265  0     -0.046"/>
      <geometry>
        <box size="0.005 0.020 0.071"/>
      </geometry>
    </collision>
    <visual name="kiro_v2__5_link_visual">
      <origin rpy="0  0  0" xyz="0       0      -0.03549"/>
      <geometry>
        <cylinder length=".092" radius=".029"/>
      </geometry>
    </visual>
    <visual name="kiro_v2__5_link_pad_visual">
      <origin rpy="0  0  0" xyz="0.0265   0      -0.03549"/>
      <geometry>
        <box size="0.005 0.020 0.092"/>
      </geometry>
    </visual>
  </link>
  <link name="kiro_v2__6_link">
    <inertial>
      <mass value="0.192"/>
      <origin rpy="0  0  0" xyz="0  0  0"/>
      <inertia ixx="390949e-9" ixy="-59e-9" ixz="346e-9" iyy="400197e-9" iyz="355e-9" izz="73725e-9"/>
    </inertial>
    <collision name="kiro_v2__6_link_collision">
      <origin rpy="0  0  0" xyz="0     0    -0.046"/>
      <geometry>
        <cylinder length=".071" radius=".029"/>
      </geometry>
    </collision>
    <collision name="kiro_v2__6_link_pad_collision">
      <origin rpy="0  0  0" xyz="0.0265  0     -0.046"/>
      <geometry>
        <box size="0.005 0.020 0.071"/>
      </geometry>
    </collision>
    <visual name="kiro_v2__6_link_visual">
      <origin rpy="0  0  0" xyz="0       0      -0.03549"/>
      <geometry>
        <cylinder length=".092" radius=".029"/>
      </geometry>
    </visual>
    <visual name="kiro_v2__6_link_pad_visual">
      <origin rpy="0  0  0" xyz="0.0265   0      -0.03549"/>
      <geometry>
        <box size="0.005 0.020 0.092"/>
      </geometry>
    </visual>
  </link>
  <link name="kiro_v2__7_link">
    <inertial>
      <mass value="0.192"/>
      <origin rpy="0  0  0" xyz="0  0  0"/>
      <inertia ixx="390949e-9" ixy="-59e-9" ixz="346e-9" iyy="400197e-9" iyz="355e-9" izz="73725e-9"/>
    </inertial>
    <collision name="kiro_v2__7_link_collision">
      <origin rpy="0  0  0" xyz="0     0    -0.046"/>
      <geometry>
        <cylinder length=".071" radius=".029"/>
      </geometry>
    </collision>
    <collision name="kiro_v2__7_link_pad_collision">
      <origin rpy="0  0  0" xyz="0.0265  0     -0.046"/>
      <geometry>
        <box size="0.005 0.020 0.071"/>
      </geometry>
    </collision>
    <visual name="kiro_v2__7_link_visual">
      <origin rpy="0  0  0" xyz="0       0      -0.03549"/>
      <geometry>
        <cylinder length=".092" radius=".029"/>
      </geometry>
    </visual>
    <visual name="kiro_v2__7_link_pad_visual">
      <origin rpy="0  0  0" xyz="0.0265   0      -0.03549"/>
      <geometry>
        <box size="0.005 0.020 0.092"/>
      </geometry>
    </visual>
  </link>
  <link name="kiro_v2__8_link">
    <inertial>
      <mass value="0.192"/>
      <origin rpy="0  0  0" xyz="0  0  0"/>
      <inertia ixx="390949e-9" ixy="-59e-9" ixz="346e-9" iyy="400197e-9" iyz="355e-9" izz="73725e-9"/>
    </inertial>
    <collision name="kiro_v2__8_link_collision">
      <origin rpy="0  0  0" xyz="0     0    -0.046"/>
      <geometry>
        <cylinder length=".071" radius=".029"/>
      </geometry>
    </collision>
    <collision name="kiro_v2__8_link_pad_collision">
      <origin rpy="0  0  0" xyz="0.0265  0     -0.046"/>
      <geometry>
        <box size="0.005 0.020 0.071"/>
      </geometry>
    </collision>
    <visual name="kiro_v2__8_link_visual">
      <origin rpy="0  0  0" xyz="0       0      -0.03549"/>
      <geometry>
        <cylinder length=".092" radius=".029"/>
      </geometry>
    </visual>
    <visual name="kiro_v2__8_link_pad_visual">
      <origin rpy="0  0  0" xyz="0.0265   0      -0.03549"/>
      <geometry>
        <box size="0.005 0.020 0.092"/>
      </geometry>
    </visual>
  </link>
  <link name="kiro_v2__9_link">
    <inertial>
      <mass value="0.192"/>
      <origin rpy="0  0  0" xyz="0  0  0"/>
      <inertia ixx="390949e-9" ixy="-59e-9" ixz="346e-9" iyy="400197e-9" iyz="355e-9" izz="73725e-9"/>
    </inertial>
    <collision name="kiro_v2__9_link_collision">
      <origin rpy="0  0  0" xyz="0     0    -0.046"/>
      <geometry>
        <cylinder length=".071" radius=".029"/>
      </geometry>
    </collision>
    <collision name="kiro_v2__9_link_pad_collision">
      <origin rpy="0  0  0" xyz="0.0265  0     -0.046"/>
      <geometry>
        <box size="0.005 0.020 0.071"/>
      </geometry>
    </collision>
    <visual name="kiro_v2__9_link_visual">
      <origin rpy="0  0  0" xyz="0       0      -0.03549"/>
      <geometry>
        <cylinder length=".092" radius=".029"/>
      </geometry>
    </visual>
    <visual name="kiro_v2__9_link_pad_visual">
      <origin rpy="0  0  0" xyz="0.0265   0      -0.03549"/>
      <geometry>
        <box size="0.005 0.020 0.092"/>
      </geometry>
    </visual>
  </link>
  <link name="kiro_v2__10_link">
    <inertial>
      <mass value="0.192"/>
      <origin rpy="0  0  0" xyz="0  0  0"/>
      <inertia ixx="390949e-9" ixy="-59e-9" ixz="346e-9" iyy="400197e-9" iyz="355e-9" izz="73725e-9"/>
    </inertial>
    <collision name="kiro_v2__10_link_collision">
      <origin rpy="0  0  0" xyz="0     0    -0.046"/>
      <geometry>
        <cylinder length=".071" radius=".029"/>
      </geometry>
    </collision>
    <collision name="kiro_v2__10_link_pad_collision">
      <origin rpy="0  0  0" xyz="0.0265  0     -0.046"/>
      <geometry>
        <box size="0.005 0.020 0.071"/>
      </geometry>
    </collision>
    <visual name="kiro_v2__10_link_visual">
      <origin rpy="0  0  0" xyz="0       0      -0.03549"/>
      <geometry>
        <cylinder length=".092" radius=".029"/>
      </geometry>
    </visual>
    <visual name="kiro_v2__10_link_pad_visual">
      <origin rpy="0  0  0" xyz="0.0265   0      -0.03549"/>
      <geometry>
        <box size="0.005 0.020 0.092"/>
      </geometry>
    </visual>
  </link>
  <link name="kiro_v2__11_link">
    <inertial>
      <mass value="0.192"/>
      <origin rpy="0  0  0" xyz="0  0  0"/>
      <inertia ixx="390949e-9" ixy="-59e-9" ixz="346e-9" iyy="400197e-9" iyz="355e-9" izz="73725e-9"/>
    </inertial>
    <collision name="kiro_v2__11_link_collision">
      <origin rpy="0  0  0" xyz="0     0    -0.046"/>
      <geometry>
        <cylinder length=".071" radius=".029"/>
      </geometry>
    </collision>
    <collision name="kiro_v2__11_link_pad_collision">
      <origin rpy="0  0  0" xyz="0.0265  0     -0.046"/>
      <geometry>
        <box size="0.005 0.020 0.071"/>
      </geometry>
    </collision>
    <visual name="kiro_v2__11_link_visual">
      <origin rpy="0  0  0" xyz="0       0      -0.03549"/>
      <geometry>
        <cylinder length=".092" radius=".029"/>
      </geometry>
    </visual>
    <visual name="kiro_v2__11_link_pad_visual">
      <origin rpy="0  0  0" xyz="0.0265   0      -0.03549"/>
      <geometry>
        <box size="0.005 0.020 0.092"/>
      </geometry>
    </visual>
  </link>
  <link name="kiro_v2__12_tail">
    <inertial>
      <mass value="0.192"/>
      <origin rpy="0  0  0" xyz="0  0  0"/>
      <inertia ixx="390949e-9" ixy="-59e-9" ixz="346e-9" iyy="400197e-9" iyz="355e-9" izz="73725e-9"/>
    </inertial>
    <collision name="kiro_v2__12_tail_collision">
      <origin rpy="0  0  0" xyz="0     0    -0.046"/>
      <geometry>
        <cylinder length=".071" radius=".029"/>
      </geometry>
    </collision>
    <collision name="kiro_v2__12_tail_pad_collision">
      <origin rpy="0  0  0" xyz="0.0265  0     -0.046"/>
      <geometry>
        <box size="0.005 0.020 0.071"/>
      </geometry>
    </collision>
    <visual name="kiro_v2__12_tail_visual">
      <origin rpy="0  0  0" xyz="0       0      -0.03549"/>
      <geometry>
        <cylinder length=".092" radius=".029"/>
      </geometry>
    </visual>
    <visual name="kiro_v2__12_tail_pad_visual">
      <origin rpy="0  0  0" xyz="0.0265   0      -0.03549"/>
      <geometry>
        <box size="0.005 0.020 0.092"/>
      </geometry>
    </visual>
  </link>
</robot>
